2020-11-13 10:59:13,016-log.py-<module>-DEBUG-19-TEST for logging
2020-11-13 10:59:13,084-tools.py-extract_log-INFO-100-

开始执行程序2：提取配种记录
2020-11-13 10:59:13,088-tools.py-extract_log-INFO-101-参数为：
  配种记录文件['配种记录_2020年10月_蚌埠.xlsx,配种记录_2020年10月_和林.xlsx,配种记录_2020年10月_马鞍山.xlsx,配种记录_2020年10月_洪雅.xlsx配种记录_2020年10月_宝鸡.xlsx']
2020-11-13 10:59:13,089-tools.py-extract_log-ERROR-110-错误:
Traceback (most recent call last):
  File "c:\Users\runda\OneDrive - RundaTech\PortableApps\PortableApps\VSCode\data\ToolsALTA\tools.py", line 105, in extract_log
    act = main(f)
  File "c:\Users\runda\OneDrive - RundaTech\PortableApps\PortableApps\VSCode\data\ToolsALTA\tools.py", line 76, in main
    full_file_name_i = os.path.join(DIR, 'BredLog', file)
NameError: name 'DIR' is not defined

2020-11-13 11:02:15,865-log.py-<module>-DEBUG-19-TEST for logging
2020-11-13 11:02:15,936-tools.py-extract_log-INFO-100-

开始执行程序2：提取配种记录
2020-11-13 11:02:15,938-tools.py-extract_log-INFO-101-参数为：
  配种记录文件['配种记录_2020年10月_蚌埠.xlsx,配种记录_2020年10月_和林.xlsx,配种记录_2020年10月_马鞍山.xlsx,配种记录_2020年10月_洪雅.xlsx配种记录_2020年10月_宝鸡.xlsx']
2020-11-13 11:02:15,957-tools.py-extract_log-ERROR-110-错误:
Traceback (most recent call last):
  File "c:\Users\runda\OneDrive - RundaTech\PortableApps\PortableApps\VSCode\data\ToolsALTA\tools.py", line 105, in extract_log
    act = main(f)
  File "c:\Users\runda\OneDrive - RundaTech\PortableApps\PortableApps\VSCode\data\ToolsALTA\tools.py", line 77, in main
    bred_log = pd.DataFrame(pd.read_excel(full_file_name_i))
  File "C:\Anaconda3\lib\site-packages\pandas\io\excel\_base.py", line 304, in read_excel
    io = ExcelFile(io, engine=engine)
  File "C:\Anaconda3\lib\site-packages\pandas\io\excel\_base.py", line 821, in __init__
    self._reader = self._engines[engine](self._io)
  File "C:\Anaconda3\lib\site-packages\pandas\io\excel\_xlrd.py", line 21, in __init__
    super().__init__(filepath_or_buffer)
  File "C:\Anaconda3\lib\site-packages\pandas\io\excel\_base.py", line 353, in __init__
    self.book = self.load_workbook(filepath_or_buffer)
  File "C:\Anaconda3\lib\site-packages\pandas\io\excel\_xlrd.py", line 36, in load_workbook
    return open_workbook(filepath_or_buffer)
  File "C:\Anaconda3\lib\site-packages\xlrd\__init__.py", line 111, in open_workbook
    with open(filename, "rb") as f:
FileNotFoundError: [Errno 2] No such file or directory: 'c:\\Users\\runda\\OneDrive - RundaTech\\04 工作\\0405 艾格威贸易\\ALTA_Matching\\\\BredLog\\配种记录_2020年10月_蚌埠.xlsx,配种记录_2020年10月_和林.xlsx,配种记录_2020年10月_马鞍山.xlsx,配种记录_2020年10月_洪雅.xlsx配种记录_2020年10月_宝鸡.xlsx'

2020-11-13 11:04:35,692-log.py-<module>-DEBUG-19-TEST for logging
2020-11-13 11:04:35,870-tools.py-extract_log-INFO-100-

开始执行程序2：提取配种记录
2020-11-13 11:04:35,907-tools.py-extract_log-INFO-101-参数为：
  配种记录文件['配种记录_2020年10月_蚌埠.xlsx,配种记录_2020年10月_和林.xlsx,', '配种记录_2020年10月_马鞍山.xlsx,配种记录_2020年10月_洪雅.xlsx,配种记录_2020年10月_宝鸡.xlsx']
2020-11-13 11:04:35,926-tools.py-extract_log-ERROR-110-错误:
Traceback (most recent call last):
  File "c:\Users\runda\OneDrive - RundaTech\PortableApps\PortableApps\VSCode\data\ToolsALTA\tools.py", line 105, in extract_log
    act = main(f)
  File "c:\Users\runda\OneDrive - RundaTech\PortableApps\PortableApps\VSCode\data\ToolsALTA\tools.py", line 77, in main
    bred_log = pd.DataFrame(pd.read_excel(full_file_name_i))
  File "C:\Anaconda3\lib\site-packages\pandas\io\excel\_base.py", line 304, in read_excel
    io = ExcelFile(io, engine=engine)
  File "C:\Anaconda3\lib\site-packages\pandas\io\excel\_base.py", line 821, in __init__
    self._reader = self._engines[engine](self._io)
  File "C:\Anaconda3\lib\site-packages\pandas\io\excel\_xlrd.py", line 21, in __init__
    super().__init__(filepath_or_buffer)
  File "C:\Anaconda3\lib\site-packages\pandas\io\excel\_base.py", line 353, in __init__
    self.book = self.load_workbook(filepath_or_buffer)
  File "C:\Anaconda3\lib\site-packages\pandas\io\excel\_xlrd.py", line 36, in load_workbook
    return open_workbook(filepath_or_buffer)
  File "C:\Anaconda3\lib\site-packages\xlrd\__init__.py", line 111, in open_workbook
    with open(filename, "rb") as f:
FileNotFoundError: [Errno 2] No such file or directory: 'c:\\Users\\runda\\OneDrive - RundaTech\\04 工作\\0405 艾格威贸易\\ALTA_Matching\\\\BredLog\\配种记录_2020年10月_蚌埠.xlsx,配种记录_2020年10月_和林.xlsx,'

2020-11-13 11:06:23,734-log.py-<module>-DEBUG-19-TEST for logging
2020-11-13 11:06:23,797-tools.py-extract_log-INFO-100-

开始执行程序2：提取配种记录
2020-11-13 11:06:23,800-tools.py-extract_log-INFO-101-参数为：
  配种记录文件['配种记录_2020年10月_蚌埠.xlsx,', '配种记录_2020年10月_和林.xlsx,', '配种记录_2020年10月_马鞍山.xlsx,', '配种记录_2020年10月_洪雅.xlsx,', '配种记录_2020年10月_宝鸡.xlsx']
2020-11-13 11:06:23,848-tools.py-extract_log-ERROR-110-错误:
Traceback (most recent call last):
  File "c:\Users\runda\OneDrive - RundaTech\PortableApps\PortableApps\VSCode\data\ToolsALTA\tools.py", line 105, in extract_log
    act = main(f)
  File "c:\Users\runda\OneDrive - RundaTech\PortableApps\PortableApps\VSCode\data\ToolsALTA\tools.py", line 77, in main
    bred_log = pd.DataFrame(pd.read_excel(full_file_name_i))
  File "C:\Anaconda3\lib\site-packages\pandas\io\excel\_base.py", line 304, in read_excel
    io = ExcelFile(io, engine=engine)
  File "C:\Anaconda3\lib\site-packages\pandas\io\excel\_base.py", line 821, in __init__
    self._reader = self._engines[engine](self._io)
  File "C:\Anaconda3\lib\site-packages\pandas\io\excel\_xlrd.py", line 21, in __init__
    super().__init__(filepath_or_buffer)
  File "C:\Anaconda3\lib\site-packages\pandas\io\excel\_base.py", line 353, in __init__
    self.book = self.load_workbook(filepath_or_buffer)
  File "C:\Anaconda3\lib\site-packages\pandas\io\excel\_xlrd.py", line 36, in load_workbook
    return open_workbook(filepath_or_buffer)
  File "C:\Anaconda3\lib\site-packages\xlrd\__init__.py", line 111, in open_workbook
    with open(filename, "rb") as f:
FileNotFoundError: [Errno 2] No such file or directory: 'c:\\Users\\runda\\OneDrive - RundaTech\\04 工作\\0405 艾格威贸易\\ALTA_Matching\\\\BredLog\\配种记录_2020年10月_蚌埠.xlsx,'

2020-11-13 11:11:43,319-log.py-<module>-DEBUG-19-TEST for logging
2020-11-13 11:12:23,324-log.py-<module>-DEBUG-19-TEST for logging
2020-11-13 11:12:23,401-tools.py-extract_log-INFO-100-

开始执行程序2：提取配种记录
2020-11-13 11:12:23,401-tools.py-extract_log-INFO-101-参数为：
  配种记录文件['配种记录_2020年10月_蚌埠.xlsx,', '配种记录_2020年10月_和林.xlsx,', '配种记录_2020年10月_马鞍山.xlsx,', '配种记录_2020年10月_洪雅.xlsx,', '配种记录_2020年10月_宝鸡.xlsx']
2020-11-13 11:12:23,434-tools.py-extract_log-ERROR-110-错误:
Traceback (most recent call last):
  File "c:\Users\runda\OneDrive - RundaTech\PortableApps\PortableApps\VSCode\data\ToolsALTA\tools.py", line 105, in extract_log
    act = main(f)
  File "c:\Users\runda\OneDrive - RundaTech\PortableApps\PortableApps\VSCode\data\ToolsALTA\tools.py", line 77, in main
    bred_log = pd.DataFrame(pd.read_excel(full_file_name_i))
  File "C:\Anaconda3\lib\site-packages\pandas\io\excel\_base.py", line 304, in read_excel
    io = ExcelFile(io, engine=engine)
  File "C:\Anaconda3\lib\site-packages\pandas\io\excel\_base.py", line 821, in __init__
    self._reader = self._engines[engine](self._io)
  File "C:\Anaconda3\lib\site-packages\pandas\io\excel\_xlrd.py", line 21, in __init__
    super().__init__(filepath_or_buffer)
  File "C:\Anaconda3\lib\site-packages\pandas\io\excel\_base.py", line 353, in __init__
    self.book = self.load_workbook(filepath_or_buffer)
  File "C:\Anaconda3\lib\site-packages\pandas\io\excel\_xlrd.py", line 36, in load_workbook
    return open_workbook(filepath_or_buffer)
  File "C:\Anaconda3\lib\site-packages\xlrd\__init__.py", line 111, in open_workbook
    with open(filename, "rb") as f:
FileNotFoundError: [Errno 2] No such file or directory: 'c:\\Users\\runda\\OneDrive - RundaTech\\04 工作\\0405 艾格威贸易\\ALTA_Matching\\BredLog\\配种记录_2020年10月_蚌埠.xlsx,'

2020-11-13 11:18:38,874-log.py-<module>-DEBUG-19-TEST for logging
2020-11-13 11:18:38,952-tools.py-extract_log-INFO-100-

开始执行程序2：提取配种记录
2020-11-13 11:18:38,954-tools.py-extract_log-INFO-101-参数为：
  配种记录文件['配种记录_2020年10月_蚌埠.xlsx', '配种记录_2020年10月_和林.xlsx', '配种记录_2020年10月_马鞍山.xlsx', '配种记录_2020年10月_洪雅.xlsx', '配种记录_2020年10月_宝鸡.xlsx']
2020-11-13 11:18:40,845-tools.py-extract_log-ERROR-110-错误:
Traceback (most recent call last):
  File "c:\Users\runda\OneDrive - RundaTech\PortableApps\PortableApps\VSCode\data\ToolsALTA\tools.py", line 84, in main
    '上次配种', '备注'
  File "C:\Anaconda3\lib\site-packages\pandas\core\frame.py", line 2806, in __getitem__
    indexer = self.loc._get_listlike_indexer(key, axis=1, raise_missing=True)[1]
  File "C:\Anaconda3\lib\site-packages\pandas\core\indexing.py", line 1552, in _get_listlike_indexer
    keyarr, indexer, o._get_axis_number(axis), raise_missing=raise_missing
  File "C:\Anaconda3\lib\site-packages\pandas\core\indexing.py", line 1645, in _validate_read_indexer
    raise KeyError(f"{not_found} not in index")
KeyError: "['胎次', '与配公牛', '配后状态', '配种模式', '上次配种', '配前所属类别', '配种员', '事件发生日期', '耳号', '舍组床', '参配时产后天数'] not in index"

During handling of the above exception, another exception occurred:

Traceback (most recent call last):
  File "c:\Users\runda\OneDrive - RundaTech\PortableApps\PortableApps\VSCode\data\ToolsALTA\tools.py", line 105, in extract_log
    act = main(f)
  File "c:\Users\runda\OneDrive - RundaTech\PortableApps\PortableApps\VSCode\data\ToolsALTA\tools.py", line 91, in main
    '上次配种日期', '备注'
  File "C:\Anaconda3\lib\site-packages\pandas\core\frame.py", line 2806, in __getitem__
    indexer = self.loc._get_listlike_indexer(key, axis=1, raise_missing=True)[1]
  File "C:\Anaconda3\lib\site-packages\pandas\core\indexing.py", line 1552, in _get_listlike_indexer
    keyarr, indexer, o._get_axis_number(axis), raise_missing=raise_missing
  File "C:\Anaconda3\lib\site-packages\pandas\core\indexing.py", line 1645, in _validate_read_indexer
    raise KeyError(f"{not_found} not in index")
KeyError: "['繁育状态'] not in index"

2020-11-13 11:27:26,945-log.py-<module>-DEBUG-19-TEST for logging
2020-11-13 11:27:28,075-matchingTools.py-<module>-DEBUG-1559-Yes
2020-11-13 11:27:28,571-matchingTools.py-<module>-INFO-1588-程序启动成功!
2020-11-13 11:27:28,946-matchingTools.py-<module>-INFO-1589-版本：2.3-20200805
2020-11-13 11:28:14,805-tools.py-extract_log-INFO-100-

开始执行程序2：提取配种记录
2020-11-13 11:28:14,821-tools.py-extract_log-INFO-101-参数为：
  配种记录文件['配种记录_2020年10月_蚌埠.xlsx', '配种记录_2020年10月_和林.xlsx', '配种记录_2020年10月_马鞍山.xlsx', '配种记录_2020年10月_洪雅.xlsx', '配种记录_2020年10月_宝鸡.xlsx']
2020-11-13 11:28:14,821-tools.py-extract_log-INFO-105-开始处理第1个配种记录
2020-11-13 11:28:16,662-tools.py-extract_log-ERROR-111-错误:
Traceback (most recent call last):
  File "c:\Users\runda\OneDrive - RundaTech\PortableApps\PortableApps\VSCode\data\ToolsALTA\tools.py", line 84, in main
    '上次配种', '备注'
  File "C:\Anaconda3\lib\site-packages\pandas\core\frame.py", line 2806, in __getitem__
    indexer = self.loc._get_listlike_indexer(key, axis=1, raise_missing=True)[1]
  File "C:\Anaconda3\lib\site-packages\pandas\core\indexing.py", line 1552, in _get_listlike_indexer
    keyarr, indexer, o._get_axis_number(axis), raise_missing=raise_missing
  File "C:\Anaconda3\lib\site-packages\pandas\core\indexing.py", line 1645, in _validate_read_indexer
    raise KeyError(f"{not_found} not in index")
KeyError: "['舍组床', '参配时产后天数', '胎次', '配种员', '与配公牛', '配后状态', '上次配种', '配前所属类别', '耳号', '事件发生日期', '配种模式'] not in index"

During handling of the above exception, another exception occurred:

Traceback (most recent call last):
  File "c:\Users\runda\OneDrive - RundaTech\PortableApps\PortableApps\VSCode\data\ToolsALTA\tools.py", line 106, in extract_log
    act = main(f)
  File "c:\Users\runda\OneDrive - RundaTech\PortableApps\PortableApps\VSCode\data\ToolsALTA\tools.py", line 91, in main
    '上次配种日期', '备注'
  File "C:\Anaconda3\lib\site-packages\pandas\core\frame.py", line 2806, in __getitem__
    indexer = self.loc._get_listlike_indexer(key, axis=1, raise_missing=True)[1]
  File "C:\Anaconda3\lib\site-packages\pandas\core\indexing.py", line 1552, in _get_listlike_indexer
    keyarr, indexer, o._get_axis_number(axis), raise_missing=raise_missing
  File "C:\Anaconda3\lib\site-packages\pandas\core\indexing.py", line 1645, in _validate_read_indexer
    raise KeyError(f"{not_found} not in index")
KeyError: "['繁育状态'] not in index"

2020-11-13 11:28:16,717-matchingTools.py-out_error-DEBUG-48-错误: 错误:
Traceback (most recent call last):
  File "c:\Users\runda\OneDrive - RundaTech\PortableApps\PortableApps\VSCode\data\ToolsALTA\tools.py", line 84, in main
    '上次配种', '备注'
  File "C:\Anaconda3\lib\site-packages\pandas\core\frame.py", line 2806, in __getitem__
    indexer = self.loc._get_listlike_indexer(key, axis=1, raise_missing=True)[1]
  File "C:\Anaconda3\lib\site-packages\pandas\core\indexing.py", line 1552, in _get_listlike_indexer
    keyarr, indexer, o._get_axis_number(axis), raise_missing=raise_missing
  File "C:\Anaconda3\lib\site-packages\pandas\core\indexing.py", line 1645, in _validate_read_indexer
    raise KeyError(f"{not_found} not in index")
KeyError: "['舍组床', '参配时产后天数', '胎次', '配种员', '与配公牛', '配后状态', '上次配种', '配前所属类别', '耳号', '事件发生日期', '配种模式'] not in index"

During handling of the above exception, another exception occurred:

Traceback (most recent call last):
  File "c:\Users\runda\OneDrive - RundaTech\PortableApps\PortableApps\VSCode\data\ToolsALTA\tools.py", line 106, in extract_log
    act = main(f)
  File "c:\Users\runda\OneDrive - RundaTech\PortableApps\PortableApps\VSCode\data\ToolsALTA\tools.py", line 91, in main
    '上次配种日期', '备注'
  File "C:\Anaconda3\lib\site-packages\pandas\core\frame.py", line 2806, in __getitem__
    indexer = self.loc._get_listlike_indexer(key, axis=1, raise_missing=True)[1]
  File "C:\Anaconda3\lib\site-packages\pandas\core\indexing.py", line 1552, in _get_listlike_indexer
    keyarr, indexer, o._get_axis_number(axis), raise_missing=raise_missing
  File "C:\Anaconda3\lib\site-packages\pandas\core\indexing.py", line 1645, in _validate_read_indexer
    raise KeyError(f"{not_found} not in index")
KeyError: "['繁育状态'] not in index"

2020-11-13 11:28:24,433-matchingTools.py-quite-INFO-1552-程序退出：
2020-11-13 11:31:18,778-log.py-<module>-DEBUG-19-TEST for logging
2020-11-13 11:31:56,896-log.py-<module>-DEBUG-19-TEST for logging
2020-11-13 11:31:56,994-tools.py-extract_log-INFO-100-

开始执行程序2：提取配种记录
2020-11-13 11:31:57,004-tools.py-extract_log-INFO-101-参数为：
  配种记录文件['配种记录_2020年10月_蚌埠.xlsx', '配种记录_2020年10月_和林.xlsx', '配种记录_2020年10月_马鞍山.xlsx', '配种记录_2020年10月_洪雅.xlsx', '配种记录_2020年10月_宝鸡.xlsx']
2020-11-13 11:31:57,004-tools.py-extract_log-INFO-105-开始处理第1个配种记录
2020-11-13 11:32:06,973-tools.py-extract_log-INFO-107-已处理第1个配种记录, 结果保存在：c:\Users\runda\OneDrive - RundaTech\04 工作\0405 艾格威贸易\ALTA_Matching\BredLog\配种记录_2020年10月_蚌埠_结果.csv
2020-11-13 11:32:06,973-tools.py-extract_log-INFO-105-开始处理第2个配种记录
2020-11-13 11:32:07,428-tools.py-extract_log-INFO-107-已处理第2个配种记录, 结果保存在：c:\Users\runda\OneDrive - RundaTech\04 工作\0405 艾格威贸易\ALTA_Matching\BredLog\配种记录_2020年10月_和林_结果.csv
2020-11-13 11:32:07,428-tools.py-extract_log-INFO-105-开始处理第3个配种记录
2020-11-13 11:32:07,901-tools.py-extract_log-INFO-107-已处理第3个配种记录, 结果保存在：c:\Users\runda\OneDrive - RundaTech\04 工作\0405 艾格威贸易\ALTA_Matching\BredLog\配种记录_2020年10月_马鞍山_结果.csv
2020-11-13 11:32:07,901-tools.py-extract_log-INFO-105-开始处理第4个配种记录
2020-11-13 11:32:08,335-tools.py-extract_log-INFO-107-已处理第4个配种记录, 结果保存在：c:\Users\runda\OneDrive - RundaTech\04 工作\0405 艾格威贸易\ALTA_Matching\BredLog\配种记录_2020年10月_洪雅_结果.csv
2020-11-13 11:32:08,336-tools.py-extract_log-INFO-105-开始处理第5个配种记录
2020-11-13 11:32:10,153-tools.py-extract_log-INFO-107-已处理第5个配种记录, 结果保存在：c:\Users\runda\OneDrive - RundaTech\04 工作\0405 艾格威贸易\ALTA_Matching\BredLog\配种记录_2020年10月_宝鸡_结果.csv
2020-11-13 11:32:10,154-tools.py-extract_log-INFO-113-执行程序2完成：提取配种记录！
2020-11-13 11:43:35,520-log.py-<module>-DEBUG-19-TEST for logging
2020-11-13 11:43:35,575-tools.py-extract_log-INFO-100-

开始执行程序2：提取配种记录
2020-11-13 11:43:35,577-tools.py-extract_log-INFO-101-参数为：
  配种记录文件['配种记录_2020年10月_蚌埠.xlsx', '配种记录_2020年10月_和林.xlsx', '配种记录_2020年10月_马鞍山.xlsx', '配种记录_2020年10月_洪雅.xlsx', '配种记录_2020年10月_宝鸡.xlsx']
2020-11-13 11:43:35,579-tools.py-extract_log-INFO-105-开始处理第1个配种记录
2020-11-13 11:43:37,787-tools.py-extract_log-ERROR-111-错误:
Traceback (most recent call last):
  File "c:\Users\runda\OneDrive - RundaTech\PortableApps\PortableApps\VSCode\data\ToolsALTA\tools.py", line 84, in main
    '上次配种', '备注'
  File "C:\Anaconda3\lib\site-packages\pandas\core\frame.py", line 2806, in __getitem__
    indexer = self.loc._get_listlike_indexer(key, axis=1, raise_missing=True)[1]
  File "C:\Anaconda3\lib\site-packages\pandas\core\indexing.py", line 1552, in _get_listlike_indexer
    keyarr, indexer, o._get_axis_number(axis), raise_missing=raise_missing
  File "C:\Anaconda3\lib\site-packages\pandas\core\indexing.py", line 1645, in _validate_read_indexer
    raise KeyError(f"{not_found} not in index")
KeyError: "['配前所属类别', '上次配种', '耳号', '配种员', '配后状态', '舍组床', '与配公牛', '胎次', '参配时产后天数', '配种模式', '事件发生日期'] not in index"

During handling of the above exception, another exception occurred:

Traceback (most recent call last):
  File "c:\Users\runda\OneDrive - RundaTech\PortableApps\PortableApps\VSCode\data\ToolsALTA\tools.py", line 106, in extract_log
    act = main(f)
  File "c:\Users\runda\OneDrive - RundaTech\PortableApps\PortableApps\VSCode\data\ToolsALTA\tools.py", line 91, in main
    '上次配种日期', '备注'
  File "C:\Anaconda3\lib\site-packages\pandas\core\frame.py", line 2806, in __getitem__
    indexer = self.loc._get_listlike_indexer(key, axis=1, raise_missing=True)[1]
  File "C:\Anaconda3\lib\site-packages\pandas\core\indexing.py", line 1552, in _get_listlike_indexer
    keyarr, indexer, o._get_axis_number(axis), raise_missing=raise_missing
  File "C:\Anaconda3\lib\site-packages\pandas\core\indexing.py", line 1645, in _validate_read_indexer
    raise KeyError(f"{not_found} not in index")
KeyError: "['繁育状态'] not in index"

2020-11-13 11:50:00,214-tools.py-extract_log-INFO-100-

开始执行程序2：提取配种记录
2020-11-13 11:50:00,217-tools.py-extract_log-INFO-101-参数为：
  配种记录文件['配种记录_2020年10月_蚌埠.xlsx', '配种记录_2020年10月_和林.xlsx', '配种记录_2020年10月_马鞍山.xlsx', '配种记录_2020年10月_洪雅.xlsx', '配种记录_2020年10月_宝鸡.xlsx']
2020-11-13 11:50:00,218-tools.py-extract_log-INFO-105-开始处理第1个配种记录
2020-11-13 11:50:04,383-tools.py-extract_log-ERROR-111-错误:
Traceback (most recent call last):
  File "c:\Users\runda\OneDrive - RundaTech\PortableApps\PortableApps\VSCode\data\ToolsALTA\tools.py", line 84, in main
    '上次配种', '备注'
  File "C:\Anaconda3\lib\site-packages\pandas\core\frame.py", line 2806, in __getitem__
    indexer = self.loc._get_listlike_indexer(key, axis=1, raise_missing=True)[1]
  File "C:\Anaconda3\lib\site-packages\pandas\core\indexing.py", line 1552, in _get_listlike_indexer
    keyarr, indexer, o._get_axis_number(axis), raise_missing=raise_missing
  File "C:\Anaconda3\lib\site-packages\pandas\core\indexing.py", line 1645, in _validate_read_indexer
    raise KeyError(f"{not_found} not in index")
KeyError: "['参配时产后天数', '耳号', '舍组床', '配后状态', '胎次', '配前所属类别', '配种模式', '上次配种', '事件发生日期', '与配公牛', '配种员'] not in index"

During handling of the above exception, another exception occurred:

Traceback (most recent call last):
  File "c:\Users\runda\OneDrive - RundaTech\PortableApps\PortableApps\VSCode\data\ToolsALTA\tools.py", line 106, in extract_log
    act = main(f)
  File "c:\Users\runda\OneDrive - RundaTech\PortableApps\PortableApps\VSCode\data\ToolsALTA\tools.py", line 91, in main
    '上次配种日期', '备注'
  File "C:\Anaconda3\lib\site-packages\pandas\core\frame.py", line 2806, in __getitem__
    indexer = self.loc._get_listlike_indexer(key, axis=1, raise_missing=True)[1]
  File "C:\Anaconda3\lib\site-packages\pandas\core\indexing.py", line 1552, in _get_listlike_indexer
    keyarr, indexer, o._get_axis_number(axis), raise_missing=raise_missing
  File "C:\Anaconda3\lib\site-packages\pandas\core\indexing.py", line 1645, in _validate_read_indexer
    raise KeyError(f"{not_found} not in index")
KeyError: "['繁育状态'] not in index"

2020-11-13 16:57:11,810-matchingTools.py-<module>-INFO-1588-程序启动成功!
2020-11-13 16:57:12,143-matchingTools.py-<module>-INFO-1589-版本：2.3-20200805
2020-11-13 16:57:22,425-matchingTools.py-quite-INFO-1552-程序退出：
